Workbook

Sheet Terminologies

Sheet Instructions
A1: Sr No | B1: Particulars
A2: 1 | B2: Each Region will have a unique Area Name, OLT ID & Cluster ID.
A3: =A2+1 -> 2 | B3: Every FAT/OLD/FDC/JC will have a unique ID.
A4: =A3+1 -> 3 | B4: Each entity as mentioned in above pt, will have a separate row & respective entry in the tracker | R4: Item Name
A5: =A4+1 -> 4 | B5: Kindly refer Terminologies sheet for model understanding. Alternatively you can also use respective SLDs for the same | R5: FDC
A6: =A5+1 -> 5 | B6: For filling the trackers, regional teams will have to fill cells where Headings are not highlighted. | R6: FAT Box
A7: =A6+1 -> 6 | B7: Central Team will be filling data for cells where Headings are highlighted in Yellow | R7: Duct
A8: =A7+1 -> 7 | B8: Kindly do not fill any cell where headings are highlighted in Green. | R8: Primary Splitter
A9: =A8+1 -> 8 | B9: For all FAT/FDC there will be an entry of separate row in "Node Details" sheet.
A10: =A9+1 -> 9 | B10: Any extension of current path,route will be treated as a new route.
A11: =A10+1 -> 10 | B11: Any new branch getting deployed from same common FAT/FDC which is not part of existing route shall be treated as a New Route.
A12: =A11+1 -> 11 | B12: Fiber Material & Fiber Execution service details are to be entered in "Route Details" & "Node Details" sheet only.
A13: =A12+1 -> 12 | B13: Tracker has to be filled all routes that are RFS/Deployed irrespective of Sign-off.
A14: =A13+1 -> 13 | B14: Billing start date will be HOTO date, when penetration % is >=50% | R14: Secondary Splitter
A15: =A14+1 -> 14 | B15: Kindly enter date in DD_MMM_YYYY format for all columns where date has to be entered. | R15: Pigtail
A16: =A15+1 -> 15 | B16: Kindly do not alter format of the sheet, i.e add or delete rows/columns or do any formatting changes. | R16: Patch Cords
R17: Tiffin Box
R18: FMS

Sheet Route-Details
O1: =SUBTOTAL(9,O3:O1048576) -> 67231 | W1: =SUBTOTAL(9,W3:W1048576) -> 67231 | X1: =SUBTOTAL(9,X3:X1048576) -> 67231 | AE1: =SUBTOTAL(9,AE3:AE1048576) -> 67231 | AL1: =SUBTOTAL(9,AL3:AL1048576) -> 67231 | BB1: =SUBTOTAL(9,BB3:BB1048576) -> 67231 | BC1: =SUBTOTAL(9,BC3:BC1048576) -> 2016930
A2: Sr No | B2: Unique Route ID | C2: FDC/FAT Unique ID (Start Point) | D2: Start point Latlong | E2: FDC/FAT Unique ID (End Point) | F2: End point Latlong | G2: Customer | H2: Area Name | I2: City | J2: Telecom Circle | K2: State | L2: OLT ID | M2: Cluster ID | N2: Online AT Date (Delivered) | O2: Online AT Length (Delivered) | P2: HOTO Date | Q2: HOTO Signoff Date | R2: Start Date (Date from which we can bill) | S2: Lock-in Period | T2: Surrender Date | U2: Fresh Delivery/Renewal | V2: Fiber Capacity | W2: OTDR length (in meters) | X2: Customer Billable length (in meters) | Z2: Customer PO no | AA2: PO length | AB2: PO Date | AC2: PO Rate | AE2: Fiber length deployed/used (in meters) | AF2: Fiber Type | AG2: Fiber Capacity | AH2: Fiber Rate per meter (incl Freight) | AI2: Fiber Material Cost | AK2: Execution Vendor Name | AL2: Vendor Billable Length (Fiber laying) | AM2: Fiber Laying Rate | AN2: Fiber Laying/Execution Cost | AO2: OTM Length | AP2: OTM Execution Rate | AQ2: OTM Cost | AR2: Total Vendor Cost | AT2: Vendor PO No | AU2: Vendor PO Date | AV2: Vendor PO Rate | AW2: Vendor PO Cost | AY2: Vendor Invoice No | AZ2: Vendor Invoice Date | BA2: Vendor Invoice Rate | BB2: Vendor Invoiced length | BC2: Invoice Amt | BE2: Route no | BF2: Unique Route ID | BG2: Status as on March 23 | BH2: Status as on Sep 23 | BI2: Statsu as on March 2024 | BJ2: VM Remark 1 | BK2: VM Remark 2
A3: 1 | B3: 0000001PS-00001PS10 | C3: 1PS | D3: 18.5135706,73.8474076 | E3: 1PS10 | F3: 18.5132478,73.849171 | G3: Airtel | H3: Narayan Peth 1 | I3: Pune | J3: M&G | K3: Maharashtra | L3: 1PS | M3: 1PS | N3: 45046 | O3: 1600 | P3: 45046 | Q3: 45145 | R3: 45107 | U3: Fresh | V3: 24F | W3: 1600 | X3: 1600 | Z3: BAL-ANG-UASL-ROM-Maharashtra/PUR/10001850 | AA3: 150000 | AB3: 44918 | AC3: 30.5 | AE3: 1600 | AF3: ADSS | AG3: 24F | AH3: 29.43 | AI3: =IF(AE3<>"",AH3*AE3,0) -> 47088 | AK3: Tirumala Enterprises | AL3: 1600 | AM3: 30 | AN3: =IF(AL3<>"",AM3*AL3,0) -> 48000 | AQ3: =IF(AO3<>"",AP3*AO3,0) -> 0 | AR3: =AQ3+AN3 -> 48000 | AT3: ETIPL-PUR-ORD-23-09-00024 | AU3: 45180 | AV3: =AM3 -> 30 | AW3: =AV3*AL3 -> 48000 | AY3: TE/23-24/214 | AZ3: 45180 | BA3: =AM3 -> 30 | BB3: =AL3 -> 1600 | BC3: =IF(BB3<>"",BB3*BA3,0) -> 48000 | BE3: R-1 | BF3: 0000001PS-00001PS10 | BG3: NA | BH3: Completed | BI3: Completed | BJ3: New data for Sep-23 Audit
A4: =A3+1 -> 2 | B4: 00001PS09-00001PS13 | C4: 1PS09 | D4: 18.5128762,73.8498843 | E4: 1PS13 | F4: 18.5132241,73.8495957 | G4: Airtel | H4: Narayan Peth 1 | I4: Pune | J4: M&G | K4: Maharashtra | L4: 1PS | M4: 1PS | N4: 45046 | O4: 580 | P4: 45046 | Q4: 45145 | R4: 45107 | U4: Fresh | V4: 24F | W4: 580 | X4: 580 | Z4: BAL-ANG-UASL-ROM-Maharashtra/PUR/10001850 | AA4: 150000 | AB4: 44918 | AC4: 30.5 | AE4: 580 | AF4: ADSS | AG4: 24F | AH4: 29.43 | AI4: =IF(AE4<>"",AH4*AE4,0) -> 17069.4 | AK4: Tirumala Enterprises | AL4: 580 | AM4: 30 | AN4: =IF(AL4<>"",AM4*AL4,0) -> 17400 | AQ4: =IF(AO4<>"",AP4*AO4,0) -> 0 | AR4: =AQ4+AN4 -> 17400 | AT4: ETIPL-PUR-ORD-23-09-00024 | AU4: 45180 | AV4: =AM4 -> 30 | AW4: =AV4*AL4 -> 17400 | AY4: TE/23-24/214 | AZ4: 45180 | BA4: =AM4 -> 30 | BB4: =AL4 -> 580 | BC4: =IF(BB4<>"",BB4*BA4,0) -> 17400 | BE4: R-2 | BF4: 00001PS09-00001PS13 | BG4: NA | BH4: Completed | BI4: Completed | BJ4: New data for Sep-23 Audit
A5: =A4+1 -> 3 | B5: 00001PS06-00001PS15 | C5: 1PS06 | D5: 18.5131637,73.848134 | E5: 1PS15 | F5: 18.513298,73.8483325 | G5: Airtel | H5: Narayan Peth 1 | I5: Pune | J5: M&G | K5: Maharashtra | L5: 1PS | M5: 1PS | N5: 45046 | O5: 176 | P5: 45046 | Q5: 45145 | R5: 45107 | U5: Fresh | V5: 24F | W5: 176 | X5: 176 | Z5: BAL-ANG-UASL-ROM-Maharashtra/PUR/10001850 | AA5: 150000 | AB5: 44918 | AC5: 30.5 | AE5: 176 | AF5: ADSS | AG5: 24F | AH5: 29.43 | AI5: =IF(AE5<>"",AH5*AE5,0) -> 5179.68 | AK5: Tirumala Enterprises | AL5: 176 | AM5: 30 | AN5: =IF(AL5<>"",AM5*AL5,0) -> 5280 | AQ5: =IF(AO5<>"",AP5*AO5,0) -> 0 | AR5: =AQ5+AN5 -> 5280 | AT5: ETIPL-PUR-ORD-23-09-00024 | AU5: 45180 | AV5: =AM5 -> 30 | AW5: =AV5*AL5 -> 5280 | AY5: TE/23-24/214 | AZ5: 45180 | BA5: =AM5 -> 30 | BB5: =AL5 -> 176 | BC5: =IF(BB5<>"",BB5*BA5,0) -> 5280 | BE5: R-3 | BF5: 00001PS06-00001PS15 | BG5: NA | BH5: Completed | BI5: Completed | BJ5: New data for Sep-23 Audit
A6: =A5+1 -> 4 | B6: 0000001PS-00001PS16 | C6: 1PS | D6: 18.5135706,73.8474076 | E6: 1PS16 | F6: 18.512756,73.847585 | G6: Airtel | H6: Narayan Peth 1 | I6: Pune | J6: M&G | K6: Maharashtra | L6: 1PS | M6: 1PS | N6: 45046 | O6: 233 | P6: 45046 | Q6: 45145 | R6: 45107 | U6: Fresh | V6: 24F | W6: 233 | X6: 233 | Z6: BAL-ANG-UASL-ROM-Maharashtra/PUR/10001850 | AA6: 150000 | AB6: 44918 | AC6: 30.5 | AE6: 233 | AF6: ADSS | AG6: 24F | AH6: 29.43 | AI6: =IF(AE6<>"",AH6*AE6,0) -> 6857.19 | AK6: Tirumala Enterprises | AL6: 233 | AM6: 30 | AN6: =IF(AL6<>"",AM6*AL6,0) -> 6990 | AQ6: =IF(AO6<>"",AP6*AO6,0) -> 0 | AR6: =AQ6+AN6 -> 6990 | AT6: ETIPL-PUR-ORD-23-09-00024 | AU6: 45180 | AV6: =AM6 -> 30 | AW6: =AV6*AL6 -> 6990 | AY6: TE/23-24/214 | AZ6: 45180 | BA6: =AM6 -> 30 | BB6: =AL6 -> 233 | BC6: =IF(BB6<>"",BB6*BA6,0) -> 6990 | BE6: R-4 | BF6: 0000001PS-00001PS16 | BG6: NA | BH6: Completed | BI6: Completed | BJ6: New data for Sep-23 Audit
A7: =A6+1 -> 5 | B7: 00001PS02-1PS020101 | C7: 1PS02 | D7: 18.5135706,73.8474076 | E7: 1PS020101 | F7: 18.5135706,73.8474076 | G7: Airtel | H7: Narayan Peth 1 | I7: Pune | J7: M&G | K7: Maharashtra | L7: 1PS | M7: 1PS | N7: 45046 | O7: 290 | P7: 45046 | Q7: 45145 | R7: 45107 | U7: Fresh | V7: 12F | W7: 290 | X7: 290 | Z7: BAL-ANG-UASL-ROM-Maharashtra/PUR/10001850 | AA7: 200000 | AB7: 44918 | AC7: 25.5 | AE7: 290 | AF7: ADSS | AG7: 12F | AH7: 12.718 | AI7: =IF(AE7<>"",AH7*AE7,0) -> 3688.22 | AK7: Tirumala Enterprises | AL7: 290 | AM7: 30 | AN7: =IF(AL7<>"",AM7*AL7,0) -> 8700 | AQ7: =IF(AO7<>"",AP7*AO7,0) -> 0 | AR7: =AQ7+AN7 -> 8700 | AT7: ETIPL-PUR-ORD-23-09-00024 | AU7: 45180 | AV7: =AM7 -> 30 | AW7: =AV7*AL7 -> 8700 | AY7: TE/23-24/214 | AZ7: 45180 | BA7: =AM7 -> 30 | BB7: =AL7 -> 290 | BC7: =IF(BB7<>"",BB7*BA7,0) -> 8700 | BE7: R-5 | BF7: 00001PS02-1PS020101 | BG7: NA | BH7: Completed | BI7: Completed | BJ7: New data for Sep-23 Audit
A8: =A7+1 -> 6 | B8: 00001PS03-1PS030102 | C8: 1PS03 | D8: 18.5124853,73.8488461 | E8: 1PS030102 | F8: 18.5123786,73.8485078 | G8: Airtel | H8: Narayan Peth 1 | I8: Pune | J8: M&G | K8: Maharashtra | L8: 1PS | M8: 1PS | N8: 45046 | O8: 283 | P8: 45046 | Q8: 45145 | R8: 45107 | U8: Fresh | V8: 12F | W8: 283 | X8: 283 | Z8: BAL-ANG-UASL-ROM-Maharashtra/PUR/10001850 | AA8: 200000 | AB8: 44918 | AC8: 25.5 | AE8: 283 | AF8: ADSS | AG8: 12F | AH8: 12.718 | AI8: =IF(AE8<>"",AH8*AE8,0) -> 3599.194 | AK8: Tirumala Enterprises | AL8: 283 | AM8: 30 | AN8: =IF(AL8<>"",AM8*AL8,0) -> 8490 | AQ8: =IF(AO8<>"",AP8*AO8,0) -> 0 | AR8: =AQ8+AN8 -> 8490 | AT8: ETIPL-PUR-ORD-23-09-00024 | AU8: 45180 | AV8: =AM8 -> 30 | AW8: =AV8*AL8 -> 8490 | AY8: TE/23-24/214 | AZ8: 45180 | BA8: =AM8 -> 30 | BB8: =AL8 -> 283 | BC8: =IF(BB8<>"",BB8*BA8,0) -> 8490 | BE8: R-6 | BF8: 00001PS03-1PS030102 | BG8: NA | BH8: Completed | BI8: Completed | BJ8: New data for Sep-23 Audit
A9: =A8+1 -> 7 | B9: 00001PS04-1PS030101 | C9: 1PS04 | D9: 18.512749,73.8479542 | E9: 1PS030101 | F9: 18.5124853,73.8488461 | G9: Airtel | H9: Narayan Peth 1 | I9: Pune | J9: M&G | K9: Maharashtra | L9: 1PS | M9: 1PS | N9: 45046 | O9: 5 | P9: 45046 | Q9: 45145 | R9: 45107 | U9: Fresh | V9: 12F | W9: 5 | X9: 5 | Z9: BAL-ANG-UASL-ROM-Maharashtra/PUR/10001850 | AA9: 200000 | AB9: 44918 | AC9: 25.5 | AE9: 5 | AF9: ADSS | AG9: 12F | AH9: 12.718 | AI9: =IF(AE9<>"",AH9*AE9,0) -> 63.59 | AK9: Tirumala Enterprises | AL9: 5 | AM9: 30 | AN9: =IF(AL9<>"",AM9*AL9,0) -> 150 | AQ9: =IF(AO9<>"",AP9*AO9,0) -> 0 | AR9: =AQ9+AN9 -> 150 | AT9: ETIPL-PUR-ORD-23-09-00024 | AU9: 45180 | AV9: =AM9 -> 30 | AW9: =AV9*AL9 -> 150 | AY9: TE/23-24/214 | AZ9: 45180 | BA9: =AM9 -> 30 | BB9: =AL9 -> 5 | BC9: =IF(BB9<>"",BB9*BA9,0) -> 150 | BE9: R-7 | BF9: 00001PS04-1PS030101 | BG9: NA | BH9: Completed | BI9: Completed | BJ9: New data for Sep-23 Audit
A10: =A9+1 -> 8 | B10: 00001PS04-1PS040101 | C10: 1PS04 | D10: 18.512749,73.8479542 | E10: 1PS040101 | F10: 18.512749,73.8479542 | G10: Airtel | H10: Narayan Peth 1 | I10: Pune | J10: M&G | K10: Maharashtra | L10: 1PS | M10: 1PS | N10: 45046 | O10: 5 | P10: 45046 | Q10: 45145 | R10: 45107 | U10: Fresh | V10: 12F | W10: 5 | X10: 5 | Z10: BAL-ANG-UASL-ROM-Maharashtra/PUR/10001850 | AA10: 200000 | AB10: 44918 | AC10: 25.5 | AE10: 5 | AF10: ADSS | AG10: 12F | AH10: 12.718 | AI10: =IF(AE10<>"",AH10*AE10,0) -> 63.59 | AK10: Tirumala Enterprises | AL10: 5 | AM10: 30 | AN10: =IF(AL10<>"",AM10*AL10,0) -> 150 | AQ10: =IF(AO10<>"",AP10*AO10,0) -> 0 | AR10: =AQ10+AN10 -> 150 | AT10: ETIPL-PUR-ORD-23-09-00024 | AU10: 45180 | AV10: =AM10 -> 30 | AW10: =AV10*AL10 -> 150 | AY10: TE/23-24/214 | AZ10: 45180 | BA10: =AM10 -> 30 | BB10: =AL10 -> 5 | BC10: =IF(BB10<>"",BB10*BA10,0) -> 150 | BE10: R-8 | BF10: 00001PS04-1PS040101 | BG10: NA | BH10: Completed | BI10: Completed | BJ10: New data for Sep-23 Audit
A11: =A10+1 -> 9 | B11: 00001PS05-1PS050101 | C11: 1PS05 | D11: 18.5137452,73.8490588 | E11: 1PS050101 | F11: 18.5137452,73.8490588 | G11: Airtel | H11: Narayan Peth 1 | I11: Pune | J11: M&G | K11: Maharashtra | L11: 1PS | M11: 1PS | N11: 45046 | O11: 15 | P11: 45046 | Q11: 45145 | R11: 45107 | U11: Fresh | V11: 12F | W11: 15 | X11: 15 | Z11: BAL-ANG-UASL-ROM-Maharashtra/PUR/10001850 | AA11: 200000 | AB11: 44918 | AC11: 25.5 | AE11: 15 | AF11: ADSS | AG11: 12F | AH11: 12.718 | AI11: =IF(AE11<>"",AH11*AE11,0) -> 190.77 | AK11: Tirumala Enterprises | AL11: 15 | AM11: 30 | AN11: =IF(AL11<>"",AM11*AL11,0) -> 450 | AQ11: =IF(AO11<>"",AP11*AO11,0) -> 0 | AR11: =AQ11+AN11 -> 450 | AT11: ETIPL-PUR-ORD-23-09-00024 | AU11: 45180 | AV11: =AM11 -> 30 | AW11: =AV11*AL11 -> 450 | AY11: TE/23-24/214 | AZ11: 45180 | BA11: =AM11 -> 30 | BB11: =AL11 -> 15 | BC11: =IF(BB11<>"",BB11*BA11,0) -> 450 | BE11: R-9 | BF11: 00001PS05-1PS050101 | BG11: NA | BH11: Completed | BI11: Completed | BJ11: New data for Sep-23 Audit
A12: =A11+1 -> 10 | B12: 00001PS06-1PS060101 | C12: 1PS06 | D12: 18.5131637,73.848134 | E12: 1PS060101 | F12: 18.5131637,73.848134 | G12: Airtel | H12: Narayan Peth 1 | I12: Pune | J12: M&G | K12: Maharashtra | L12: 1PS | M12: 1PS | N12: 45046 | O12: 334 | P12: 45046 | Q12: 45145 | R12: 45107 | U12: Fresh | V12: 12F | W12: 334 | X12: 334 | Z12: BAL-ANG-UASL-ROM-Maharashtra/PUR/10001850 | AA12: 200000 | AB12: 44918 | AC12: 25.5 | AE12: 334 | AF12: ADSS | AG12: 12F | AH12: 12.718 | AI12: =IF(AE12<>"",AH12*AE12,0) -> 4247.812 | AK12: Tirumala Enterprises | AL12: 334 | AM12: 30 | AN12: =IF(AL12<>"",AM12*AL12,0) -> 10020 | AQ12: =IF(AO12<>"",AP12*AO12,0) -> 0 | AR12: =AQ12+AN12 -> 10020 | AT12: ETIPL-PUR-ORD-23-09-00024 | AU12: 45180 | AV12: =AM12 -> 30 | AW12: =AV12*AL12 -> 10020 | AY12: TE/23-24/214 | AZ12: 45180 | BA12: =AM12 -> 30 | BB12: =AL12 -> 334 | BC12: =IF(BB12<>"",BB12*BA12,0) -> 10020 | BE12: R-10 | BF12: 00001PS06-1PS060101 | BG12: NA | BH12: Completed | BI12: Completed | BJ12: New data for Sep-23 Audit
A13: =A12+1 -> 11 | B13: 00001PS07-1PS070101 | C13: 1PS07 | D13: 18.513012,73.8492633 | E13: 1PS070101 | F13: 18.513012,73.8492633 | G13: Airtel | H13: Narayan Peth 1 | I13: Pune | J13: M&G | K13: Maharashtra | L13: 1PS | M13: 1PS | N13: 45046 | O13: 353 | P13: 45046 | Q13: 45145 | R13: 45107 | U13: Fresh | V13: 12F | W13: 353 | X13: 353 | Z13: BAL-ANG-UASL-ROM-Maharashtra/PUR/10001850 | AA13: 200000 | AB13: 44918 | AC13: 25.5 | AE13: 353 | AF13: ADSS | AG13: 12F | AH13: 12.718 | AI13: =IF(AE13<>"",AH13*AE13,0) -> 4489.454 | AK13: Tirumala Enterprises | AL13: 353 | AM13: 30 | AN13: =IF(AL13<>"",AM13*AL13,0) -> 10590 | AQ13: =IF(AO13<>"",AP13*AO13,0) -> 0 | AR13: =AQ13+AN13 -> 10590 | AT13: ETIPL-PUR-ORD-23-09-00024 | AU13: 45180 | AV13: =AM13 -> 30 | AW13: =AV13*AL13 -> 10590 | AY13: TE/23-24/214 | AZ13: 45180 | BA13: =AM13 -> 30 | BB13: =AL13 -> 353 | BC13: =IF(BB13<>"",BB13*BA13,0) -> 10590 | BE13: R-11 | BF13: 00001PS07-1PS070101 | BG13: NA | BH13: Completed | BI13: Completed | BJ13: New data for Sep-23 Audit
A14: =A13+1 -> 12 | B14: 00001PS08-1PS080101 | C14: 1PS08 | D14: 18.512945,73.8497125 | E14: 1PS080101 | F14: 18.512945,73.8497125 | G14: Airtel | H14: Narayan Peth 1 | I14: Pune | J14: M&G | K14: Maharashtra | L14: 1PS | M14: 1PS | N14: 45046 | O14: 20 | P14: 45046 | Q14: 45145 | R14: 45107 | U14: Fresh | V14: 12F | W14: 20 | X14: 20 | Z14: BAL-ANG-UASL-ROM-Maharashtra/PUR/10001850 | AA14: 200000 | AB14: 44918 | AC14: 25.5 | AE14: 20 | AF14: ADSS | AG14: 12F | AH14: 12.718 | AI14: =IF(AE14<>"",AH14*AE14,0) -> 254.36 | AK14: Tirumala Enterprises | AL14: 20 | AM14: 30 | AN14: =IF(AL14<>"",AM14*AL14,0) -> 600 | AQ14: =IF(AO14<>"",AP14*AO14,0) -> 0 | AR14: =AQ14+AN14 -> 600 | AT14: ETIPL-PUR-ORD-23-09-00024 | AU14: 45180 | AV14: =AM14 -> 30 | AW14: =AV14*AL14 -> 600 | AY14: TE/23-24/214 | AZ14: 45180 | BA14: =AM14 -> 30 | BB14: =AL14 -> 20 | BC14: =IF(BB14<>"",BB14*BA14,0) -> 600 | BE14: R-12 | BF14: 00001PS08-1PS080101 | BG14: NA | BH14: Completed | BI14: Completed | BJ14: New data for Sep-23 Audit
A15: =A14+1 -> 13 | B15: 00001PS09-1PS090101 | C15: 1PS09 | D15: 18.5128762,73.8498843 | E15: 1PS090101 | F15: 18.5128762,73.8498843 | G15: Airtel | H15: Narayan Peth 1 | I15: Pune | J15: M&G | K15: Maharashtra | L15: 1PS | M15: 1PS | N15: 45046 | O15: 167 | P15: 45046 | Q15: 45145 | R15: 45107 | U15: Fresh | V15: 12F | W15: 167 | X15: 167 | Z15: BAL-ANG-UASL-ROM-Maharashtra/PUR/10001850 | AA15: 200000 | AB15: 44918 | AC15: 25.5 | AE15: 167 | AF15: ADSS | AG15: 12F | AH15: 12.718 | AI15: =IF(AE15<>"",AH15*AE15,0) -> 2123.906 | AK15: Tirumala Enterprises | AL15: 167 | AM15: 30 | AN15: =IF(AL15<>"",AM15*AL15,0) -> 5010 | AQ15: =IF(AO15<>"",AP15*AO15,0) -> 0 | AR15: =AQ15+AN15 -> 5010 | AT15: ETIPL-PUR-ORD-23-09-00024 | AU15: 45180 | AV15: =AM15 -> 30 | AW15: =AV15*AL15 -> 5010 | AY15: TE/23-24/214 | AZ15: 45180 | BA15: =AM15 -> 30 | BB15: =AL15 -> 167 | BC15: =IF(BB15<>"",BB15*BA15,0) -> 5010 | BE15: R-13 | BF15: 00001PS09-1PS090101 | BG15: NA | BH15: Completed | BI15: Completed | BJ15: New data for Sep-23 Audit
... A95: =A94+1 -> 93 | B95: 0000SHT57-SHT570101 | C95: SHT57 | D95: 18.5123253,73.8461169 | E95: SHT570101 | F95: 18.5123253,73.8461169 | G95: Airtel | H95: Narayan Peth 2 | I95: Pune | J95: M&G | K95: Maharashtra | L95: SHT | M95: SHT | N95: 45046 | O95: 5 | P95: 45046 | Q95: 45145 | R95: 45107 | U95: Fresh | V95: 12F | W95: 5 | X95: 5 | Z95: BAL-ANG-UASL-ROM-Maharashtra/PUR/10001850 | AA95: 200000 | AB95: 44918 | AC95: 25.5 | AE95: 5 | AF95: ADSS | AG95: 12F | AH95: 12.718 | AI95: =IF(AE95<>"",AH95*AE95,0) -> 63.59 | AK95: Yashashree Constructions | AL95: 5 | AM95: 20 | AN95: =IF(AL95<>"",AM95*AL95,0) -> 100 | AQ95: =IF(AO95<>"",AP95*AO95,0) -> 0 | AR95: =AQ95+AN95 -> 100 | AT95: ETIPL-PUR-ORD-23-07-00050 | AU95: 45128 | AV95: =AM95 -> 20 | AW95: =AV95*AL95 -> 100 | AY95: YC1249 | AZ95: 45204 | BA95: =AM95 -> 20 | BB95: =AL95 -> 5 | BC95: =IF(BB95<>"",BB95*BA95,0) -> 100 | BE95: R-91 | BF95: 0000SHT57-SHT570101 | BG95: NA | BH95: Completed | BI95: Completed | BJ95: New data for Sep-23 Audit
A96: =A95+1 -> 94 | B96: 00001WB17-SHT580108 | C96: 1WB17 | D96: 18.5117684,73.848405 | E96: SHT580108 | F96: 18.512337,73.850021 | G96: Airtel | H96: Narayan Peth 2 | I96: Pune | J96: M&G | K96: Maharashtra | L96: SHT | M96: SHT | N96: 45046 | O96: 112 | P96: 45046 | Q96: 45145 | R96: 45107 | U96: Fresh | V96: 12F | W96: 112 | X96: 112 | Z96: BAL-ANG-UASL-ROM-Maharashtra/PUR/10001850 | AA96: 200000 | AB96: 44918 | AC96: 25.5 | AE96: 112 | AF96: ADSS | AG96: 12F | AH96: 12.718 | AI96: =IF(AE96<>"",AH96*AE96,0) -> 1424.416 | AK96: Yashashree Constructions | AL96: 112 | AM96: 20 | AN96: =IF(AL96<>"",AM96*AL96,0) -> 2240 | AQ96: =IF(AO96<>"",AP96*AO96,0) -> 0 | AR96: =AQ96+AN96 -> 2240 | AT96: ETIPL-PUR-ORD-23-07-00050 | AU96: 45128 | AV96: =AM96 -> 20 | AW96: =AV96*AL96 -> 2240 | AY96: YC1250 | AZ96: 45204 | BA96: =AM96 -> 20 | BB96: =AL96 -> 112 | BC96: =IF(BB96<>"",BB96*BA96,0) -> 2240 | BE96: R-92 | BF96: 00001WB17-SHT580108 | BG96: NA | BH96: Completed | BI96: Completed | BJ96: New data for Sep-23 Audit | BK96: Credit note raised for 1 mtr.-YC1250/CN
A97: =A96+1 -> 95 | B97: 00001WB17-SHT580108 | C97: 1WB17 | D97: 18.5117684,73.848405 | E97: SHT580108 | F97: 18.512337,73.850021 | G97: Airtel | H97: Narayan Peth 2 | I97: Pune | J97: M&G | K97: Maharashtra | L97: SHT | M97: SHT | N97: 45107 | O97: 150 | P97: 45107 | Q97: 45145 | R97: 45107 | U97: Fresh | V97: 12F | W97: 150 | X97: 150 | Z97: BAL-ANG-UASL-ROM-Maharashtra/PUR/10001850 | AA97: 200000 | AB97: 44918 | AC97: 25.5 | AE97: 150 | AF97: ADSS | AG97: 12F | AH97: 15.353 | AI97: =IF(AE97<>"",AH97*AE97,0) -> 2302.95 | AK97: Yashashree Constructions | AL97: 150 | AM97: 20 | AN97: =IF(AL97<>"",AM97*AL97,0) -> 3000 | AQ97: =IF(AO97<>"",AP97*AO97,0) -> 0 | AR97: =AQ97+AN97 -> 3000 | AT97: ETIPL-PUR-ORD-23-07-00050 | AU97: 45128 | AV97: =AM97 -> 20 | AW97: =AV97*AL97 -> 3000 | AY97: YC1250 | AZ97: 45204 | BA97: =AM97 -> 20 | BB97: =AL97 -> 150 | BC97: =IF(BB97<>"",BB97*BA97,0) -> 3000 | BE97: R-92 | BF97: 00001WB17-SHT580108 | BG97: NA | BH97: Completed | BI97: Completed | BJ97: New data for Sep-23 Audit | BK97: Credit note raised for 1 mtr.-YC1250/CN
A98: =A97+1 -> 96 | B98: 0000SHT58-SHT580103 | C98: SHT58 | D98: 18.5117653,73.8488452 | E98: SHT580103 | F98: 18.511496,73.8490098 | G98: Airtel | H98: Narayan Peth 2 | I98: Pune | J98: M&G | K98: Maharashtra | L98: SHT | M98: SHT | N98: 45046 | O98: 6 | P98: 45046 | Q98: 45145 | R98: 45107 | U98: Fresh | V98: 12F | W98: 6 | X98: 6 | Z98: BAL-ANG-UASL-ROM-Maharashtra/PUR/10001850 | AA98: 200000 | AB98: 44918 | AC98: 25.5 | AE98: 6 | AF98: ADSS | AG98: 12F | AH98: 12.718 | AI98: =IF(AE98<>"",AH98*AE98,0) -> 76.308 | AK98: Yashashree Constructions | AL98: 6 | AM98: 20 | AN98: =IF(AL98<>"",AM98*AL98,0) -> 120 | AQ98: =IF(AO98<>"",AP98*AO98,0) -> 0 | AR98: =AQ98+AN98 -> 120 | AT98: ETIPL-PUR-ORD-23-07-00050 | AU98: 45128 | AV98: =AM98 -> 20 | AW98: =AV98*AL98 -> 120 | AY98: YC1250 | AZ98: 45204 | BA98: =AM98 -> 20 | BB98: =AL98 -> 6 | BC98: =IF(BB98<>"",BB98*BA98,0) -> 120 | BE98: R-93 | BF98: 0000SHT58-SHT580103 | BG98: NA | BH98: Completed | BI98: Completed | BJ98: New data for Sep-23 Audit | BK98: Credit note raised for 1 mtr.-YC1250/CN
A99: =A98+1 -> 97 | B99: 0000SHT58-SHT580102 | C99: SHT58 | D99: 18.5117653,73.8488452 | E99: SHT580102 | F99: 18.5112754,73.8490174 | G99: Airtel | H99: Narayan Peth 2 | I99: Pune | J99: M&G | K99: Maharashtra | L99: SHT | M99: SHT | N99: 45046 | O99: 4 | P99: 45046 | Q99: 45145 | R99: 45107 | U99: Fresh | V99: 12F | W99: 4 | X99: 4 | Z99: BAL-ANG-UASL-ROM-Maharashtra/PUR/10001850 | AA99: 200000 | AB99: 44918 | AC99: 25.5 | AE99: 4 | AF99: ADSS | AG99: 12F | AH99: 12.718 | AI99: =IF(AE99<>"",AH99*AE99,0) -> 50.872 | AK99: Yashashree Constructions | AL99: 4 | AM99: 20 | AN99: =IF(AL99<>"",AM99*AL99,0) -> 80 | AQ99: =IF(AO99<>"",AP99*AO99,0) -> 0 | AR99: =AQ99+AN99 -> 80 | AT99: ETIPL-PUR-ORD-23-07-00050 | AU99: 45128 | AV99: =AM99 -> 20 | AW99: =AV99*AL99 -> 80 | AY99: YC1249 | AZ99: 45204 | BA99: =AM99 -> 20 | BB99: =AL99 -> 4 | BC99: =IF(BB99<>"",BB99*BA99,0) -> 80 | BE99: R-94 | BF99: 0000SHT58-SHT580102 | BG99: NA | BH99: Completed | BI99: Completed | BJ99: New data for Sep-23 Audit
A100: =A99+1 -> 98 | B100: 0000SHT58-SHT580101 | C100: SHT58 | D100: 18.5117653,73.8488452 | E100: SHT580101 | F100: 18.5117653,73.8488452 | G100: Airtel | H100: Narayan Peth 2 | I100: Pune | J100: M&G | K100: Maharashtra | L100: SHT | M100: SHT | N100: 45046 | O100: 5 | P100: 45046 | Q100: 45145 | R100: 45107 | U100: Fresh | V100: 12F | W100: 5 | X100: 5 | Z100: BAL-ANG-UASL-ROM-Maharashtra/PUR/10001850 | AA100: 200000 | AB100: 44918 | AC100: 25.5 | AE100: 5 | AF100: ADSS | AG100: 12F | AH100: 12.718 | AI100: =IF(AE100<>"",AH100*AE100,0) -> 63.59 | AK100: Yashashree Constructions | AL100: 5 | AM100: 20 | AN100: =IF(AL100<>"",AM100*AL100,0) -> 100 | AQ100: =IF(AO100<>"",AP100*AO100,0) -> 0 | AR100: =AQ100+AN100 -> 100 | AT100: ETIPL-PUR-ORD-23-07-00050 | AU100: 45128 | AV100: =AM100 -> 20 | AW100: =AV100*AL100 -> 100 | AY100: YC1249 | AZ100: 45204 | BA100: =AM100 -> 20 | BB100: =AL100 -> 5 | BC100: =IF(BB100<>"",BB100*BA100,0) -> 100 | BE100: R-95 | BF100: 0000SHT58-SHT580101 | BG100: NA | BH100: Completed | BI100: Completed | BJ100: New data for Sep-23 Audit
A101: =A100+1 -> 99 | B101: 0000SHT60-SHT590108 | C101: SHT60 | D101: 18.5122351,73.8504507 | E101: SHT590108 | F101: 18.5123599,73.8481544 | G101: Airtel | H101: Narayan Peth 2 | I101: Pune | J101: M&G | K101: Maharashtra | L101: SHT | M101: SHT | N101: 45107 | O101: 366 | P101: 45107 | Q101: 45145 | R101: 45107 | U101: Fresh | V101: 12F | W101: 366 | X101: 366 | Z101: BAL-ANG-UASL-ROM-Maharashtra/PUR/10001850 | AA101: 200000 | AB101: 44918 | AC101: 25.5 | AE101: 366 | AF101: ADSS | AG101: 12F | AH101: 15.353 | AI101: =IF(AE101<>"",AH101*AE101,0) -> 5619.198 | AK101: Yashashree Constructions | AL101: 366 | AM101: 20 | AN101: =IF(AL101<>"",AM101*AL101,0) -> 7320 | AQ101: =IF(AO101<>"",AP101*AO101,0) -> 0 | AR101: =AQ101+AN101 -> 7320 | AT101: ETIPL-PUR-ORD-23-07-00050 | AU101: 45128 | AV101: =AM101 -> 20 | AW101: =AV101*AL101 -> 7320 | AY101: YC1250 | AZ101: 45204 | BA101: =AM101 -> 20 | BB101: =AL101 -> 366 | BC101: =IF(BB101<>"",BB101*BA101,0) -> 7320 | BE101: R-96 | BF101: 0000SHT60-SHT590108 | BG101: NA | BH101: Completed | BI101: Completed | BJ101: New data for Sep-23 Audit | BK101: Credit note raised for 1 mtr.-YC1250/CN
A102: =A101+1 -> 100 | B102: SHT590105-SHT590106 | C102: SHT590105 | D102: 18.5123777,73.848194 | E102: SHT590106 | F102: 18.5123844,73.8478181 | G102: Airtel | H102: Narayan Peth 2 | I102: Pune | J102: M&G | K102: Maharashtra | L102: SHT | M102: SHT | N102: 45107 | O102: 5 | P102: 45107 | Q102: 45145 | R102: 45107 | U102: Fresh | V102: 12F | W102: 5 | X102: 5 | Z102: BAL-ANG-UASL-ROM-Maharashtra/PUR/10001850 | AA102: 200000 | AB102: 44918 | AC102: 25.5 | AE102: 5 | AF102: ADSS | AG102: 12F | AH102: 15.353 | AI102: =IF(AE102<>"",AH102*AE102,0) -> 76.765 | AK102: Yashashree Constructions | AL102: 5 | AM102: 20 | AN102: =IF(AL102<>"",AM102*AL102,0) -> 100 | AQ102: =IF(AO102<>"",AP102*AO102,0) -> 0 | AR102: =AQ102+AN102 -> 100 | AT102: ETIPL-PUR-ORD-23-07-00050 | AU102: 45128 | AV102: =AM102 -> 20 | AW102: =AV102*AL102 -> 100 | AY102: YC1250 | AZ102: 45204 | BA102: =AM102 -> 20 | BB102: =AL102 -> 5 | BC102: =IF(BB102<>"",BB102*BA102,0) -> 100 | BE102: R-97 | BF102: SHT590105-SHT590106 | BG102: NA | BH102: Completed | BI102: Completed | BJ102: New data for Sep-23 Audit | BK102: Credit note raised for 1 mtr.-YC1250/CN
A103: =A102+1 -> 101 | B103: 0000SHT59-SHT590104 | C103: SHT59 | D103: 18.5124017,73.8481311 | E103: SHT590104 | F103: 18.5124134,73.8482089 | G103: Airtel | H103: Narayan Peth 2 | I103: Pune | J103: M&G | K103: Maharashtra | L103: SHT | M103: SHT | N103: 45107 | O103: 75 | P103: 45107 | Q103: 45145 | R103: 45107 | U103: Fresh | V103: 12F | W103: 75 | X103: 75 | Z103: BAL-ANG-UASL-ROM-Maharashtra/PUR/10001850 | AA103: 200000 | AB103: 44918 | AC103: 25.5 | AE103: 75 | AF103: ADSS | AG103: 12F | AH103: 15.353 | AI103: =IF(AE103<>"",AH103*AE103,0) -> 1151.475 | AK103: Yashashree Constructions | AL103: 75 | AM103: 20 | AN103: =IF(AL103<>"",AM103*AL103,0) -> 1500 | AQ103: =IF(AO103<>"",AP103*AO103,0) -> 0 | AR103: =AQ103+AN103 -> 1500 | AT103: ETIPL-PUR-ORD-23-07-00050 | AU103: 45128 | AV103: =AM103 -> 20 | AW103: =AV103*AL103 -> 1500 | AY103: YC1250 | AZ103: 45204 | BA103: =AM103 -> 20 | BB103: =AL103 -> 75 | BC103: =IF(BB103<>"",BB103*BA103,0) -> 1500 | BE103: R-98 | BF103: 0000SHT59-SHT590104 | BG103: NA | BH103: Completed | BI103: Completed | BJ103: New data for Sep-23 Audit | BK103: Credit note raised for 1 mtr.-YC1250/CN
A104: =A103+1 -> 102 | B104: 0000SHT60-SHT600106 | C104: SHT60 | D104: 18.5122351,73.8504507 | E104: SHT600106 | F104: 18.5123265,73.850136 | G104: Airtel | H104: Narayan Peth 2 | I104: Pune | J104: M&G | K104: Maharashtra | L104: SHT | M104: SHT | N104: 45107 | O104: 15 | P104: 45107 | Q104: 45145 | R104: 45107 | U104: Fresh | V104: 12F | W104: 15 | X104: 15 | Z104: BAL-ANG-UASL-ROM-Maharashtra/PUR/10001850 | AA104: 200000 | AB104: 44918 | AC104: 25.5 | AE104: 15 | AF104: ADSS | AG104: 12F | AH104: 15.353 | AI104: =IF(AE104<>"",AH104*AE104,0) -> 230.295 | AK104: Yashashree Constructions | AL104: 15 | AM104: 20 | AN104: =IF(AL104<>"",AM104*AL104,0) -> 300 | AQ104: =IF(AO104<>"",AP104*AO104,0) -> 0 | AR104: =AQ104+AN104 -> 300 | AT104: ETIPL-PUR-ORD-23-07-00050 | AU104: 45128 | AV104: =AM104 -> 20 | AW104: =AV104*AL104 -> 300 | AY104: YC1250 | AZ104: 45204 | BA104: =AM104 -> 20 | BB104: =AL104 -> 15 | BC104: =IF(BB104<>"",BB104*BA104,0) -> 300 | BE104: R-99 | BF104: 0000SHT60-SHT600106 | BG104: NA | BH104: Completed | BI104: Completed | BJ104: New data for Sep-23 Audit | BK104: Credit note raised for 1 mtr.-YC1250/CN
A105: =A104+1 -> 103 | B105: 0000SHT60-SHT600103 | C105: SHT60 | D105: 18.5122351,73.8504507 | E105: SHT600103 | F105: 18.5122041,73.85051 | G105: Airtel | H105: Narayan Peth 2 | I105: Pune | J105: M&G | K105: Maharashtra | L105: SHT | M105: SHT | N105: 45107 | O105: 15 | P105: 45107 | Q105: 45145 | R105: 45107 | U105: Fresh | V105: 12F | W105: 15 | X105: 15 | Z105: BAL-ANG-UASL-ROM-Maharashtra/PUR/10001850 | AA105: 200000 | AB105: 44918 | AC105: 25.5 | AE105: 15 | AF105: ADSS | AG105: 12F | AH105: 15.353 | AI105: =IF(AE105<>"",AH105*AE105,0) -> 230.295 | AK105: Yashashree Constructions | AL105: 15 | AM105: 20 | AN105: =IF(AL105<>"",AM105*AL105,0) -> 300 | AQ105: =IF(AO105<>"",AP105*AO105,0) -> 0 | AR105: =AQ105+AN105 -> 300 | AT105: ETIPL-PUR-ORD-23-07-00050 | AU105: 45128 | AV105: =AM105 -> 20 | AW105: =AV105*AL105 -> 300 | AY105: YC1250 | AZ105: 45204 | BA105: =AM105 -> 20 | BB105: =AL105 -> 15 | BC105: =IF(BB105<>"",BB105*BA105,0) -> 300 | BE105: R-100 | BF105: 0000SHT60-SHT600103 | BG105: NA | BH105: Completed | BI105: Completed | BJ105: New data for Sep-23 Audit | BK105: Credit note raised for 1 mtr.-YC1250/CN
A106: =A105+1 -> 104 | B106: 0000SHT51-SHT610107 | C106: SHT51 | D106: 18.5117673,73.8500197 | E106: SHT610107 | F106: 18.5116494,73.8460474 | G106: Airtel | H106: Narayan Peth 2 | I106: Pune | J106: M&G | K106: Maharashtra | L106: SHT | M106: SHT | N106: 45107 | O106: 335 | P106: 45107 | Q106: 45145 | R106: 45107 | U106: Fresh | V106: 12F | W106: 335 | X106: 335 | Z106: BAL-ANG-UASL-ROM-Maharashtra/PUR/10001850 | AA106: 200000 | AB106: 44918 | AC106: 25.5 | AE106: 335 | AF106: ADSS | AG106: 12F | AH106: 12.69477 | AI106: =IF(AE106<>"",AH106*AE106,0) -> 4252.7479 | AK106: Yashashree Constructions | AL106: 335 | AM106: 20 | AN106: =IF(AL106<>"",AM106*AL106,0) -> 6700 | AQ106: =IF(AO106<>"",AP106*AO106,0) -> 0 | AR106: =AQ106+AN106 -> 6700 | AT106: ETIPL-PUR-ORD-23-07-00050 | AU106: 45128 | AV106: =AM106 -> 20 | AW106: =AV106*AL106 -> 6700 | AY106: YC1250 | AZ106: 45204 | BA106: =AM106 -> 20 | BB106: =AL106 -> 335 | BC106: =IF(BB106<>"",BB106*BA106,0) -> 6700 | BE106: R-101 | BF106: 0000SHT51-SHT610107 | BG106: NA | BH106: Completed | BI106: Completed | BJ106: New data for Sep-23 Audit | BK106: Credit note raised for 1 mtr.-YC1250/CN
A107: =A106+1 -> 105 | B107: 0000SHT61-SHT610105 | C107: SHT61 | D107: 18.5116483,73.8459884 | E107: SHT610105 | F107: 18.5116817,73.8459099 | G107: Airtel | H107: Narayan Peth 2 | I107: Pune | J107: M&G | K107: Maharashtra | L107: SHT | M107: SHT | N107: 45107 | O107: 144 | P107: 45107 | Q107: 45145 | R107: 45107 | U107: Fresh | V107: 12F | W107: 144 | X107: 144 | Z107: BAL-ANG-UASL-ROM-Maharashtra/PUR/10001850 | AA107: 200000 | AB107: 44918 | AC107: 25.5 | AE107: 144 | AF107: ADSS | AG107: 12F | AH107: 12.69477 | AI107: =IF(AE107<>"",AH107*AE107,0) -> 1828.0469 | AK107: Yashashree Constructions | AL107: 144 | AM107: 20 | AN107: =IF(AL107<>"",AM107*AL107,0) -> 2880 | AQ107: =IF(AO107<>"",AP107*AO107,0) -> 0 | AR107: =AQ107+AN107 -> 2880 | AT107: ETIPL-PUR-ORD-23-07-00050 | AU107: 45128 | AV107: =AM107 -> 20 | AW107: =AV107*AL107 -> 2880 | AY107: YC1250 | AZ107: 45204 | BA107: =AM107 -> 20 | BB107: =AL107 -> 144 | BC107: =IF(BB107<>"",BB107*BA107,0) -> 2880 | BE107: R-102 | BF107: 0000SHT61-SHT610105 | BG107: NA | BH107: Completed | BI107: Completed | BJ107: New data for Sep-23 Audit | BK107: Credit note raised for 1 mtr.-YC1250/CN
A108: =A107+1 -> 106 | B108: 0000SHT51-SHT620103 | C108: SHT51 | D108: 18.5117673,73.8500197 | E108: SHT620103 | F108: 18.5120323,73.8513231 | G108: Airtel | H108: Narayan Peth 2 | I108: Pune | J108: M&G | K108: Maharashtra | L108: SHT | M108: SHT | N108: 45107 | O108: 15 | P108: 45107 | Q108: 45145 | R108: 45107 | U108: Fresh | V108: 12F | W108: 15 | X108: 15 | Z108: BAL-ANG-UASL-ROM-Maharashtra/PUR/10001850 | AA108: 200000 | AB108: 44918 | AC108: 25.5 | AE108: 15 | AF108: ADSS | AG108: 12F | AH108: 12.69477 | AI108: =IF(AE108<>"",AH108*AE108,0) -> 190.42155 | AK108: Yashashree Constructions | AL108: 15 | AM108: 20 | AN108: =IF(AL108<>"",AM108*AL108,0) -> 300 | AQ108: =IF(AO108<>"",AP108*AO108,0) -> 0 | AR108: =AQ108+AN108 -> 300 | AT108: ETIPL-PUR-ORD-23-07-00050 | AU108: 45128 | AV108: =AM108 -> 20 | AW108: =AV108*AL108 -> 300 | AY108: YC1250 | AZ108: 45204 | BA108: =AM108 -> 20 | BB108: =AL108 -> 15 | BC108: =IF(BB108<>"",BB108*BA108,0) -> 300 | BE108: R-103 | BF108: 0000SHT51-SHT620103 | BG108: NA | BH108: Completed | BI108: Completed | BJ108: New data for Sep-23 Audit | BK108: Credit note raised for 1 mtr.-YC1250/CN
A109: =A108+1 -> 107 | B109: 0000SHT51-SHT620105 | C109: SHT51 | D109: 18.5117673,73.8500197 | E109: SHT620105 | F109: 18.5122119,73.8507445 | G109: Airtel | H109: Narayan Peth 2 | I109: Pune | J109: M&G | K109: Maharashtra | L109: SHT | M109: SHT | N109: 45107 | O109: 10 | P109: 45107 | Q109: 45145 | R109: 45107 | U109: Fresh | V109: 12F | W109: 10 | X109: 10 | Z109: BAL-ANG-UASL-ROM-Maharashtra/PUR/10001850 | AA109: 200000 | AB109: 44918 | AC109: 25.5 | AE109: 10 | AF109: ADSS | AG109: 12F | AH109: 12.69477 | AI109: =IF(AE109<>"",AH109*AE109,0) -> 126.9477 | AK109: Yashashree Constructions | AL109: 10 | AM109: 20 | AN109: =IF(AL109<>"",AM109*AL109,0) -> 200 | AQ109: =IF(AO109<>"",AP109*AO109,0) -> 0 | AR109: =AQ109+AN109 -> 200 | AT109: ETIPL-PUR-ORD-23-07-00050 | AU109: 45128 | AV109: =AM109 -> 20 | AW109: =AV109*AL109 -> 200 | AY109: YC1249 | AZ109: 45204 | BA109: =AM109 -> 20 | BB109: =AL109 -> 10 | BC109: =IF(BB109<>"",BB109*BA109,0) -> 200 | BE109: R-104 | BF109: 0000SHT51-SHT620105 | BG109: NA | BH109: Completed | BI109: Completed | BJ109: New data for Sep-23 Audit
A110: =A109+1 -> 108 | B110: 0000SHT51-SHT620107 | C110: SHT51 | D110: 18.5117673,73.8500197 | E110: SHT620107 | F110: 18.5125595,73.848233 | G110: Airtel | H110: Narayan Peth 2 | I110: Pune | J110: M&G | K110: Maharashtra | L110: SHT | M110: SHT | N110: 45107 | O110: 87 | P110: 45107 | Q110: 45145 | R110: 45107 | U110: Fresh | V110: 12F | W110: 87 | X110: 87 | Z110: BAL-ANG-UASL-ROM-Maharashtra/PUR/10001850 | AA110: 200000 | AB110: 44918 | AC110: 25.5 | AE110: 87 | AF110: ADSS | AG110: 12F | AH110: 12.69477 | AI110: =IF(AE110<>"",AH110*AE110,0) -> 1104.445 | AK110: Yashashree Constructions | AL110: 87 | AM110: 20 | AN110: =IF(AL110<>"",AM110*AL110,0) -> 1740 | AQ110: =IF(AO110<>"",AP110*AO110,0) -> 0 | AR110: =AQ110+AN110 -> 1740 | AT110: ETIPL-PUR-ORD-23-07-00050 | AU110: 45128 | AV110: =AM110 -> 20 | AW110: =AV110*AL110 -> 1740 | AY110: YC1250 | AZ110: 45204 | BA110: =AM110 -> 20 | BB110: =AL110 -> 87 | BC110: =IF(BB110<>"",BB110*BA110,0) -> 1740 | BE110: R-105 | BF110: 0000SHT51-SHT620107 | BG110: NA | BH110: Completed | BI110: Completed | BJ110: New data for Sep-23 Audit | BK110: Credit note raised for 1 mtr.-YC1250/CN
A111: =A110+1 -> 109 | B111: 0000SHT51-0000SHT62 | C111: SHT51 | D111: 18.5117673,73.8500197 | E111: SHT62 | F111: 18.5122324,73.8507676 | G111: Airtel | H111: Narayan Peth 2 | I111: Pune | J111: M&G | K111: Maharashtra | L111: SHT | M111: SHT | N111: 45107 | O111: 198 | P111: 45107 | Q111: 45145 | R111: 45107 | U111: Fresh | V111: 12F | W111: 198 | X111: 198 | Z111: BAL-ANG-UASL-ROM-Maharashtra/PUR/10001850 | AA111: 200000 | AB111: 44918 | AC111: 25.5 | AE111: 198 | AF111: ADSS | AG111: 12F | AH111: 12.69477 | AI111: =IF(AE111<>"",AH111*AE111,0) -> 2513.5645 | AK111: Yashashree Constructions | AL111: 198 | AM111: 20 | AN111: =IF(AL111<>"",AM111*AL111,0) -> 3960 | AQ111: =IF(AO111<>"",AP111*AO111,0) -> 0 | AR111: =AQ111+AN111 -> 3960 | AT111: ETIPL-PUR-ORD-23-07-00050 | AU111: 45128 | AV111: =AM111 -> 20 | AW111: =AV111*AL111 -> 3960 | AY111: YC1250 | AZ111: 45204 | BA111: =AM111 -> 20 | BB111: =AL111 -> 198 | BC111: =IF(BB111<>"",BB111*BA111,0) -> 3960 | BE111: R-106 | BF111: 0000SHT51-0000SHT62 | BG111: NA | BH111: Completed | BI111: Completed | BJ111: New data for Sep-23 Audit | BK111: Credit note raised for 1 mtr.-YC1250/CN
A112: =A111+1 -> 110 | B112: 0000SHT51-0000SHT63 | C112: SHT51 | D112: 18.5117673,73.8500197 | E112: SHT63 | F112: 18.5121777,73.8500441 | G112: Airtel | H112: Narayan Peth 2 | I112: Pune | J112: M&G | K112: Maharashtra | L112: SHT | M112: SHT | N112: 45107 | O112: 94 | P112: 45107 | Q112: 45145 | R112: 45107 | U112: Fresh | V112: 12F | W112: 94 | X112: 94 | Z112: BAL-ANG-UASL-ROM-Maharashtra/PUR/10001850 | AA112: 200000 | AB112: 44918 | AC112: 25.5 | AE112: 94 | AF112: ADSS | AG112: 12F | AH112: 12.69477 | AI112: =IF(AE112<>"",AH112*AE112,0) -> 1193.3084 | AK112: Yashashree Constructions | AL112: 94 | AM112: 20 | AN112: =IF(AL112<>"",AM112*AL112,0) -> 1880 | AQ112: =IF(AO112<>"",AP112*AO112,0) -> 0 | AR112: =AQ112+AN112 -> 1880 | AT112: ETIPL-PUR-ORD-23-07-00050 | AU112: 45128 | AV112: =AM112 -> 20 | AW112: =AV112*AL112 -> 1880 | AY112: YC1250 | AZ112: 45204 | BA112: =AM112 -> 20 | BB112: =AL112 -> 94 | BC112: =IF(BB112<>"",BB112*BA112,0) -> 1880 | BE112: R-107 | BF112: 0000SHT51-0000SHT63 | BG112: NA | BH112: Completed | BI112: Completed | BJ112: New data for Sep-23 Audit | BK112: Credit note raised for 1 mtr.-YC1250/CN
A113: =A112+1 -> 111 | B113: 0000SHT51-SHT630104 | C113: SHT51 | D113: 18.5117673,73.8500197 | E113: SHT630104 | F113: 18.5122366,73.8500087 | G113: Airtel | H113: Narayan Peth 2 | I113: Pune | J113: M&G | K113: Maharashtra | L113: SHT | M113: SHT | N113: 45107 | O113: 20 | P113: 45107 | Q113: 45145 | R113: 45107 | U113: Fresh | V113: 12F | W113: 20 | X113: 20 | Z113: BAL-ANG-UASL-ROM-Maharashtra/PUR/10001850 | AA113: 200000 | AB113: 44918 | AC113: 25.5 | AE113: 20 | AF113: ADSS | AG113: 12F | AH113: 12.69477 | AI113: =IF(AE113<>"",AH113*AE113,0) -> 253.8954 | AK113: Yashashree Constructions | AL113: 20 | AM113: 20 | AN113: =IF(AL113<>"",AM113*AL113,0) -> 400 | AQ113: =IF(AO113<>"",AP113*AO113,0) -> 0 | AR113: =AQ113+AN113 -> 400 | AT113: ETIPL-PUR-ORD-23-07-00050 | AU113: 45128 | AV113: =AM113 -> 20 | AW113: =AV113*AL113 -> 400 | AY113: YC1250 | AZ113: 45204 | BA113: =AM113 -> 20 | BB113: =AL113 -> 20 | BC113: =IF(BB113<>"",BB113*BA113,0) -> 400 | BE113: R-108 | BF113: 0000SHT51-SHT630104 | BG113: NA | BH113: Completed | BI113: Completed | BJ113: New data for Sep-23 Audit | BK113: Credit note raised for 1 mtr.-YC1250/CN
A114: =A113+1 -> 112 | B114: 0000SHT62-SHT630107 | C114: SHT62 | D114: 18.5122324,73.8507676 | E114: SHT630107 | F114: 18.5121676,73.8501893 | G114: Airtel | H114: Narayan Peth 2 | I114: Pune | J114: M&G | K114: Maharashtra | L114: SHT | M114: SHT | N114: 45107 | O114: 76 | P114: 45107 | Q114: 45145 | R114: 45107 | U114: Fresh | V114: 12F | W114: 76 | X114: 76 | Z114: BAL-ANG-UASL-ROM-Maharashtra/PUR/10001850 | AA114: 200000 | AB114: 44918 | AC114: 25.5 | AE114: 76 | AF114: ADSS | AG114: 12F | AH114: 12.69477 | AI114: =IF(AE114<>"",AH114*AE114,0) -> 964.80252 | AK114: Yashashree Constructions | AL114: 76 | AM114: 20 | AN114: =IF(AL114<>"",AM114*AL114,0) -> 1520 | AQ114: =IF(AO114<>"",AP114*AO114,0) -> 0 | AR114: =AQ114+AN114 -> 1520 | AT114: ETIPL-PUR-ORD-23-07-00050 | AU114: 45128 | AV114: =AM114 -> 20 | AW114: =AV114*AL114 -> 1520 | AY114: YC1250 | AZ114: 45204 | BA114: =AM114 -> 20 | BB114: =AL114 -> 76 | BC114: =IF(BB114<>"",BB114*BA114,0) -> 1520 | BE114: R-109 | BF114: 0000SHT62-SHT630107 | BG114: NA | BH114: Completed | BI114: Completed | BJ114: New data for Sep-23 Audit | BK114: Credit note raised for 1 mtr.-YC1250/CN
A115: =A114+1 -> 113 | B115: 000000K0E-0000K0E04 | C115: K0E | D115: 18.5096769,73.8328109 | E115: K0E04 | F115: 18.5108541,73.8314165 | G115: Airtel | H115: Prabhat Rd 1 | I115: Pune | J115: M&G | K115: Maharashtra | L115: K0E | M115: K0E | N115: 45046 | O115: 937 | P115: 45046 | Q115: 45145 | R115: 45107 | U115: Fresh | V115: 24F | W115: 937 | X115: 937 | Z115: BAL-ANG-UASL-ROM-Maharashtra/PUR/10001850 | AA115: 150000 | AB115: 44918 | AC115: 30.5 | AE115: 937 | AF115: ADSS | AG115: 24F | AH115: 29.43 | AI115: =IF(AE115<>"",AH115*AE115,0) -> 27575.91 | AK115: Tirumala Enterprises | AL115: 937 | AM115: 30 | AN115: =IF(AL115<>"",AM115*AL115,0) -> 28110 | AQ115: =IF(AO115<>"",AP115*AO115,0) -> 0 | AR115: =AQ115+AN115 -> 28110 | AT115: ETIPL-PUR-ORD-23-06-00032 | AU115: 45082 | AV115: =AM115 -> 30 | AW115: =AV115*AL115 -> 28110 | AY115: TE/23-24/165 | AZ115: 45136 | BA115: =AM115 -> 30 | BB115: =AL115 -> 937 | BC115: =IF(BB115<>"",BB115*BA115,0) -> 28110 | BE115: R-1 | BF115: 000000K0E-0000K0E04 | BG115: NA | BH115: Completed | BI115: Completed | BJ115: New data for Sep-23 Audit
A116: =A115+1 -> 114 | B116: 000000K0E-0000K0E06 | C116: K0E | D116: 18.5096769,73.8328109 | E116: K0E06 | F116: 18.5119896,73.8324053 | G116: Airtel | H116: Prabhat Rd 1 | I116: Pune | J116: M&G | K116: Maharashtra | L116: K0E | M116: K0E | N116: 45046 | O116: 1176 | P116: 45046 | Q116: 45145 | R116: 45107 | U116: Fresh | V116: 24F | W116: 1176 | X116: 1176 | Z116: BAL-ANG-UASL-ROM-Maharashtra/PUR/10001850 | AA116: 150000 | AB116: 44918 | AC116: 30.5 | AE116: 1176 | AF116: ADSS | AG116: 24F | AH116: 29.43 | AI116: =IF(AE116<>"",AH116*AE116,0) -> 34609.68 | AK116: Tirumala Enterprises | AL116: 1176 | AM116: 30 | AN116: =IF(AL116<>"",AM116*AL116,0) -> 35280 | AQ116: =IF(AO116<>"",AP116*AO116,0) -> 0 | AR116: =AQ116+AN116 -> 35280 | AT116: ETIPL-PUR-ORD-23-06-00032 | AU116: 45082 | AV116: =AM116 -> 30 | AW116: =AV116*AL116 -> 35280 | AY116: TE/23-24/165 | AZ116: 45136 | BA116: =AM116 -> 30 | BB116: =AL116 -> 1176 | BC116: =IF(BB116<>"",BB116*BA116,0) -> 35280 | BE116: R-2 | BF116: 000000K0E-0000K0E06 | BG116: NA | BH116: Completed | BI116: Completed | BJ116: New data for Sep-23 Audit
A117: =A116+1 -> 115 | B117: 000000K0E-0000K0E06 | C117: K0E | D117: 18.5096769,73.8328109 | E117: K0E06 | F117: 18.5119896,73.8324053 | G117: Airtel | H117: Prabhat Rd 1 | I117: Pune | J117: M&G | K117: Maharashtra | L117: K0E | M117: K0E | N117: 45107 | O117: 176 | P117: 45107 | Q117: 45145 | R117: 45107 | U117: Fresh | V117: 24F | W117: 176 | X117: 176 | Z117: BAL-ANG-UASL-ROM-Maharashtra/PUR/10001850 | AA117: 150000 | AB117: 44918 | AC117: 30.5 | AE117: 176 | AF117: ADSS | AG117: 24F | AH117: 29.43 | AI117: =IF(AE117<>"",AH117*AE117,0) -> 5179.68 | AK117: Tirumala Enterprises | AL117: 176 | AM117: 30 | AN117: =IF(AL117<>"",AM117*AL117,0) -> 5280 | AQ117: =IF(AO117<>"",AP117*AO117,0) -> 0 | AR117: =AQ117+AN117 -> 5280 | AT117: ETIPL-PUR-ORD-23-06-00032 | AU117: 45082 | AV117: =AM117 -> 30 | AW117: =AV117*AL117 -> 5280 | AY117: TE/23-24/165 | AZ117: 45136 | BA117: =AM117 -> 30 | BB117: =AL117 -> 176 | BC117: =IF(BB117<>"",BB117*BA117,0) -> 5280 | BE117: R-2 | BF117: 000000K0E-0000K0E06 | BG117: NA | BH117: Completed | BI117: Completed | BJ117: New data for Sep-23 Audit
A118: =A117+1 -> 116 | B118: 000000K0E-0000K0E13 | C118: K0E | D118: 18.5096769,73.8328109 | E118: K0E13 | F118: 18.5107298,73.832166 | G118: Airtel | H118: Prabhat Rd 1 | I118: Pune | J118: M&G | K118: Maharashtra | L118: K0E | M118: K0E | N118: 45046 | O118: 591 | P118: 45046 | Q118: 45145 | R118: 45107 | U118: Fresh | V118: 24F | W118: 591 | X118: 591 | Z118: BAL-ANG-UASL-ROM-Maharashtra/PUR/10001850 | AA118: 150000 | AB118: 44918 | AC118: 30.5 | AE118: 591 | AF118: ADSS | AG118: 24F | AH118: 29.43 | AI118: =IF(AE118<>"",AH118*AE118,0) -> 17393.13 | AK118: Tirumala Enterprises | AL118: 591 | AM118: 30 | AN118: =IF(AL118<>"",AM118*AL118,0) -> 17730 | AQ118: =IF(AO118<>"",AP118*AO118,0) -> 0 | AR118: =AQ118+AN118 -> 17730 | AT118: ETIPL-PUR-ORD-23-06-00032 | AU118: 45082 | AV118: =AM118 -> 30 | AW118: =AV118*AL118 -> 17730 | AY118: TE/23-24/165 | AZ118: 45136 | BA118: =AM118 -> 30 | BB118: =AL118 -> 591 | BC118: =IF(BB118<>"",BB118*BA118,0) -> 17730 | BE118: R-3 | BF118: 000000K0E-0000K0E13 | BG118: NA | BH118: Completed | BI118: Completed | BJ118: New data for Sep-23 Audit
A119: =A118+1 -> 117 | B119: 000000K0E-0000K0E07 | C119: K0E | D119: 18.5096769,73.8328109 | E119: K0E07 | F119: 18.5117783,73.8329774 | G119: Airtel | H119: Prabhat Rd 1 | I119: Pune | J119: M&G | K119: Maharashtra | L119: K0E | M119: K0E | N119: 45046 | O119: 1216 | P119: 45046 | Q119: 45145 | R119: 45107 | U119: Fresh | V119: 24F | W119: 1216 | X119: 1216 | Z119: BAL-ANG-UASL-ROM-Maharashtra/PUR/10001850 | AA119: 150000 | AB119: 44918 | AC119: 30.5 | AE119: 1216 | AF119: ADSS | AG119: 24F | AH119: 29.43 | AI119: =IF(AE119<>"",AH119*AE119,0) -> 35786.88 | AK119: Tirumala Enterprises | AL119: 1216 | AM119: 30 | AN119: =IF(AL119<>"",AM119*AL119,0) -> 36480 | AQ119: =IF(AO119<>"",AP119*AO119,0) -> 0 | AR119: =AQ119+AN119 -> 36480 | AT119: ETIPL-PUR-ORD-23-06-00032 | AU119: 45082 | AV119: =AM119 -> 30 | AW119: =AV119*AL119 -> 36480 | AY119: TE/23-24/165 | AZ119: 45136 | BA119: =AM119 -> 30 | BB119: =AL119 -> 1216 | BC119: =IF(BB119<>"",BB119*BA119,0) -> 36480 | BE119: R-4 | BF119: 000000K0E-0000K0E07 | BG119: NA | BH119: Completed | BI119: Completed | BJ119: New data for Sep-23 Audit
...

Sheet Node Details
E1: =MATCH(E2,'Route-Details'!$B$2:$X$2,0) -> 6 | F1: =MATCH(F2,'Route-Details'!$B$2:$X$2,0) -> 7 | G1: =MATCH(G2,'Route-Details'!$B$2:$X$2,0) -> 8 | H1: =MATCH(H2,'Route-Details'!$B$2:$X$2,0) -> 9 | I1: =MATCH(I2,'Route-Details'!$B$2:$X$2,0) -> 11 | J1: =MATCH(J2,'Route-Details'!$B$2:$X$2,0) -> 12 | S1: =SUBTOTAL(9,S3:S1048576) -> 0
A2: Sr No | B2: FDC/FAT Unique ID (End Point) | C2: Latlong | D2: Route ID (Route on which FAT/FDC is connected) | E2: Customer | F2: Area Name | G2: City | H2: Telecom Circle | I2: OLT ID | J2: Cluster ID | K2: Online AT Date (Delivered) | L2: HOTO Date | M2: HOTO Signoff Date | N2: Start Date (Date from which we can bill) | O2: Lock-in Period | P2: Surrender Date | Q2: Any Additional Fiber used for connectivity | R2: Fiber Capacity | S2: Online AT Length (Delivered) | T2: OTDR length (in meters) | U2: Customer Billable length (in meters) | W2: Customer PO no | X2: PO length | Y2: PO Date | Z2: PO Rate | AB2: Fiber length deployed/used (in meters) | AC2: Fiber Type | AD2: Fiber Capacity | AE2: Fiber Rate per meter (incl Freight) | AF2: Fiber Material Cost | AH2: Execution Vendor Name | AI2: Vendor Billable Length (Fiber laying) | AJ2: Fiber Laying Rate | AK2: Fiber Laying/Execution Cost | AL2: OTM Length | AM2: OTM Execution Rate | AN2: OTM Cost | AO2: Total Vendor Cost | AQ2: Vendor PO No | AR2: Vendor PO Date | AS2: Vendor PO Rate | AT2: Vendor PO Cost | AV2: Vendor Invoice No | AW2: Vendor Invoice Date | AX2: Vendor Invoice Rate | AY2: Vendor Invoiced length | AZ2: Invoice Amt | BB2: Route no | BC2: Remark
A3: 1 | B3: 1WB15 | C3: 18.5115219,73.8463387 | D3: 0000001WB-00001WB15 | E3: =_xlfn.IFNA(VLOOKUP($D3,'Route-Details'!$B$2:$X$1048576,'Node Details'!E$1,0),"") -> Airtel | F3: =_xlfn.IFNA(VLOOKUP($D3,'Route-Details'!$B$2:$X$1048576,'Node Details'!F$1,0),"") -> Narayan Peth 2 | G3: =_xlfn.IFNA(VLOOKUP($D3,'Route-Details'!$B$2:$X$1048576,'Node Details'!G$1,0),"") -> Pune | H3: =_xlfn.IFNA(VLOOKUP($D3,'Route-Details'!$B$2:$X$1048576,'Node Details'!H$1,0),"") -> M&G | I3: =_xlfn.IFNA(VLOOKUP($D3,'Route-Details'!$B$2:$X$1048576,'Node Details'!I$1,0),"") -> 1WB | J3: =_xlfn.IFNA(VLOOKUP($D3,'Route-Details'!$B$2:$X$1048576,'Node Details'!J$1,0),"") -> 1WB | K3: 45046 | L3: 45107 | M3: 45112 | N3: 45107 | Q3: No | BB3: R-22 | BC3: New data for Sep-23 Audit
A4: =A3+1 -> 2 | B4: 1WB150103 | C4: 18.5116278,73.8463653 | D4: 00001WB15-1WB150101 | E4: =_xlfn.IFNA(VLOOKUP($D4,'Route-Details'!$B$2:$X$1048576,'Node Details'!E$1,0),"") -> Airtel | F4: =_xlfn.IFNA(VLOOKUP($D4,'Route-Details'!$B$2:$X$1048576,'Node Details'!F$1,0),"") -> Narayan Peth 2 | G4: =_xlfn.IFNA(VLOOKUP($D4,'Route-Details'!$B$2:$X$1048576,'Node Details'!G$1,0),"") -> Pune | H4: =_xlfn.IFNA(VLOOKUP($D4,'Route-Details'!$B$2:$X$1048576,'Node Details'!H$1,0),"") -> M&G | I4: =_xlfn.IFNA(VLOOKUP($D4,'Route-Details'!$B$2:$X$1048576,'Node Details'!I$1,0),"") -> 1WB | J4: =_xlfn.IFNA(VLOOKUP($D4,'Route-Details'!$B$2:$X$1048576,'Node Details'!J$1,0),"") -> 1WB | K4: 45046 | L4: 45107 | M4: 45112 | N4: 45107 | Q4: No | BB4: R-25 | BC4: New data for Sep-23 Audit
A5: =A4+1 -> 3 | B5: 1WB150102 | C5: 18.5116077,73.846343 | D5: 00001WB15-1WB150101 | E5: =_xlfn.IFNA(VLOOKUP($D5,'Route-Details'!$B$2:$X$1048576,'Node Details'!E$1,0),"") -> Airtel | F5: =_xlfn.IFNA(VLOOKUP($D5,'Route-Details'!$B$2:$X$1048576,'Node Details'!F$1,0),"") -> Narayan Peth 2 | G5: =_xlfn.IFNA(VLOOKUP($D5,'Route-Details'!$B$2:$X$1048576,'Node Details'!G$1,0),"") -> Pune | H5: =_xlfn.IFNA(VLOOKUP($D5,'Route-Details'!$B$2:$X$1048576,'Node Details'!H$1,0),"") -> M&G | I5: =_xlfn.IFNA(VLOOKUP($D5,'Route-Details'!$B$2:$X$1048576,'Node Details'!I$1,0),"") -> 1WB | J5: =_xlfn.IFNA(VLOOKUP($D5,'Route-Details'!$B$2:$X$1048576,'Node Details'!J$1,0),"") -> 1WB | K5: 45046 | L5: 45107 | M5: 45112 | N5: 45107 | Q5: No | BB5: R-25 | BC5: New data for Sep-23 Audit
A6: =A5+1 -> 4 | B6: 1WB150101 | C6: 18.5115219,73.8463387 | D6: 00001WB15-1WB150101 | E6: =_xlfn.IFNA(VLOOKUP($D6,'Route-Details'!$B$2:$X$1048576,'Node Details'!E$1,0),"") -> Airtel | F6: =_xlfn.IFNA(VLOOKUP($D6,'Route-Details'!$B$2:$X$1048576,'Node Details'!F$1,0),"") -> Narayan Peth 2 | G6: =_xlfn.IFNA(VLOOKUP($D6,'Route-Details'!$B$2:$X$1048576,'Node Details'!G$1,0),"") -> Pune | H6: =_xlfn.IFNA(VLOOKUP($D6,'Route-Details'!$B$2:$X$1048576,'Node Details'!H$1,0),"") -> M&G | I6: =_xlfn.IFNA(VLOOKUP($D6,'Route-Details'!$B$2:$X$1048576,'Node Details'!I$1,0),"") -> 1WB | J6: =_xlfn.IFNA(VLOOKUP($D6,'Route-Details'!$B$2:$X$1048576,'Node Details'!J$1,0),"") -> 1WB | K6: 45046 | L6: 45107 | M6: 45112 | N6: 45107 | Q6: No | BB6: R-25 | BC6: New data for Sep-23 Audit
A7: =A6+1 -> 5 | B7: 1WB16 | C7: 18.5114659,73.8479177 | D7: 0000001WB-00001WB19 | E7: =_xlfn.IFNA(VLOOKUP($D7,'Route-Details'!$B$2:$X$1048576,'Node Details'!E$1,0),"") -> Airtel | F7: =_xlfn.IFNA(VLOOKUP($D7,'Route-Details'!$B$2:$X$1048576,'Node Details'!F$1,0),"") -> Narayan Peth 2 | G7: =_xlfn.IFNA(VLOOKUP($D7,'Route-Details'!$B$2:$X$1048576,'Node Details'!G$1,0),"") -> Pune | H7: =_xlfn.IFNA(VLOOKUP($D7,'Route-Details'!$B$2:$X$1048576,'Node Details'!H$1,0),"") -> M&G | I7: =_xlfn.IFNA(VLOOKUP($D7,'Route-Details'!$B$2:$X$1048576,'Node Details'!I$1,0),"") -> 1WB | J7: =_xlfn.IFNA(VLOOKUP($D7,'Route-Details'!$B$2:$X$1048576,'Node Details'!J$1,0),"") -> 1WB | K7: 45046 | L7: 45107 | M7: 45112 | N7: 45107 | Q7: No | BB7: R-23 | BC7: New data for Sep-23 Audit
A8: =A7+1 -> 6 | B8: 1WB160108 | C8: 18.5110529,73.8480907 | D8: 00001WB16-1WB160108 | E8: =_xlfn.IFNA(VLOOKUP($D8,'Route-Details'!$B$2:$X$1048576,'Node Details'!E$1,0),"") -> Airtel | F8: =_xlfn.IFNA(VLOOKUP($D8,'Route-Details'!$B$2:$X$1048576,'Node Details'!F$1,0),"") -> Narayan Peth 2 | G8: =_xlfn.IFNA(VLOOKUP($D8,'Route-Details'!$B$2:$X$1048576,'Node Details'!G$1,0),"") -> Pune | H8: =_xlfn.IFNA(VLOOKUP($D8,'Route-Details'!$B$2:$X$1048576,'Node Details'!H$1,0),"") -> M&G | I8: =_xlfn.IFNA(VLOOKUP($D8,'Route-Details'!$B$2:$X$1048576,'Node Details'!I$1,0),"") -> 1WB | J8: =_xlfn.IFNA(VLOOKUP($D8,'Route-Details'!$B$2:$X$1048576,'Node Details'!J$1,0),"") -> 1WB | K8: 45046 | L8: 45107 | M8: 45112 | N8: 45107 | Q8: No | BB8: R-26 | BC8: New data for Sep-23 Audit
A9: =A8+1 -> 7 | B9: 1WB160107 | C9: 18.5110637,73.8480184 | D9: 00001WB16-1WB160107 | E9: =_xlfn.IFNA(VLOOKUP($D9,'Route-Details'!$B$2:$X$1048576,'Node Details'!E$1,0),"") -> Airtel | F9: =_xlfn.IFNA(VLOOKUP($D9,'Route-Details'!$B$2:$X$1048576,'Node Details'!F$1,0),"") -> Narayan Peth 2 | G9: =_xlfn.IFNA(VLOOKUP($D9,'Route-Details'!$B$2:$X$1048576,'Node Details'!G$1,0),"") -> Pune | H9: =_xlfn.IFNA(VLOOKUP($D9,'Route-Details'!$B$2:$X$1048576,'Node Details'!H$1,0),"") -> M&G | I9: =_xlfn.IFNA(VLOOKUP($D9,'Route-Details'!$B$2:$X$1048576,'Node Details'!I$1,0),"") -> 1WB | J9: =_xlfn.IFNA(VLOOKUP($D9,'Route-Details'!$B$2:$X$1048576,'Node Details'!J$1,0),"") -> 1WB | K9: 45046 | L9: 45107 | M9: 45112 | N9: 45107 | Q9: No | BB9: R-27 | BC9: New data for Sep-23 Audit
A10: =A9+1 -> 8 | B10: 1WB160106 | C10: 18.5108534,73.8479786 | D10: 00001WB16-1WB160101 | E10: =_xlfn.IFNA(VLOOKUP($D10,'Route-Details'!$B$2:$X$1048576,'Node Details'!E$1,0),"") -> Airtel | F10: =_xlfn.IFNA(VLOOKUP($D10,'Route-Details'!$B$2:$X$1048576,'Node Details'!F$1,0),"") -> Narayan Peth 2 | G10: =_xlfn.IFNA(VLOOKUP($D10,'Route-Details'!$B$2:$X$1048576,'Node Details'!G$1,0),"") -> Pune | H10: =_xlfn.IFNA(VLOOKUP($D10,'Route-Details'!$B$2:$X$1048576,'Node Details'!H$1,0),"") -> M&G | I10: =_xlfn.IFNA(VLOOKUP($D10,'Route-Details'!$B$2:$X$1048576,'Node Details'!I$1,0),"") -> 1WB | J10: =_xlfn.IFNA(VLOOKUP($D10,'Route-Details'!$B$2:$X$1048576,'Node Details'!J$1,0),"") -> 1WB | K10: 45046 | L10: 45107 | M10: 45112 | N10: 45107 | Q10: No | BB10: R-28 | BC10: New data for Sep-23 Audit
A11: =A10+1 -> 9 | B11: 1WB160105 | C11: 18.5114569,73.8482843 | D11: 00001WB16-1WB160101 | E11: =_xlfn.IFNA(VLOOKUP($D11,'Route-Details'!$B$2:$X$1048576,'Node Details'!E$1,0),"") -> Airtel | F11: =_xlfn.IFNA(VLOOKUP($D11,'Route-Details'!$B$2:$X$1048576,'Node Details'!F$1,0),"") -> Narayan Peth 2 | G11: =_xlfn.IFNA(VLOOKUP($D11,'Route-Details'!$B$2:$X$1048576,'Node Details'!G$1,0),"") -> Pune | H11: =_xlfn.IFNA(VLOOKUP($D11,'Route-Details'!$B$2:$X$1048576,'Node Details'!H$1,0),"") -> M&G | I11: =_xlfn.IFNA(VLOOKUP($D11,'Route-Details'!$B$2:$X$1048576,'Node Details'!I$1,0),"") -> 1WB | J11: =_xlfn.IFNA(VLOOKUP($D11,'Route-Details'!$B$2:$X$1048576,'Node Details'!J$1,0),"") -> 1WB | K11: 45046 | L11: 45107 | M11: 45112 | N11: 45107 | Q11: No | BB11: R-28 | BC11: New data for Sep-23 Audit
A12: =A11+1 -> 10 | B12: 1WB160104 | C12: 18.5116228,73.8481831 | D12: 00001WB16-1WB160101 | E12: =_xlfn.IFNA(VLOOKUP($D12,'Route-Details'!$B$2:$X$1048576,'Node Details'!E$1,0),"") -> Airtel | F12: =_xlfn.IFNA(VLOOKUP($D12,'Route-Details'!$B$2:$X$1048576,'Node Details'!F$1,0),"") -> Narayan Peth 2 | G12: =_xlfn.IFNA(VLOOKUP($D12,'Route-Details'!$B$2:$X$1048576,'Node Details'!G$1,0),"") -> Pune | H12: =_xlfn.IFNA(VLOOKUP($D12,'Route-Details'!$B$2:$X$1048576,'Node Details'!H$1,0),"") -> M&G | I12: =_xlfn.IFNA(VLOOKUP($D12,'Route-Details'!$B$2:$X$1048576,'Node Details'!I$1,0),"") -> 1WB | J12: =_xlfn.IFNA(VLOOKUP($D12,'Route-Details'!$B$2:$X$1048576,'Node Details'!J$1,0),"") -> 1WB | K12: 45046 | L12: 45107 | M12: 45112 | N12: 45107 | Q12: No | BB12: R-28 | BC12: New data for Sep-23 Audit
A13: =A12+1 -> 11 | B13: 1WB160103 | C13: 18.5114684,73.8484323 | D13: 00001WB16-1WB160101 | E13: =_xlfn.IFNA(VLOOKUP($D13,'Route-Details'!$B$2:$X$1048576,'Node Details'!E$1,0),"") -> Airtel | F13: =_xlfn.IFNA(VLOOKUP($D13,'Route-Details'!$B$2:$X$1048576,'Node Details'!F$1,0),"") -> Narayan Peth 2 | G13: =_xlfn.IFNA(VLOOKUP($D13,'Route-Details'!$B$2:$X$1048576,'Node Details'!G$1,0),"") -> Pune | H13: =_xlfn.IFNA(VLOOKUP($D13,'Route-Details'!$B$2:$X$1048576,'Node Details'!H$1,0),"") -> M&G | I13: =_xlfn.IFNA(VLOOKUP($D13,'Route-Details'!$B$2:$X$1048576,'Node Details'!I$1,0),"") -> 1WB | J13: =_xlfn.IFNA(VLOOKUP($D13,'Route-Details'!$B$2:$X$1048576,'Node Details'!J$1,0),"") -> 1WB | K13: 45046 | L13: 45107 | M13: 45112 | N13: 45107 | Q13: No | BB13: R-28 | BC13: New data for Sep-23 Audit
A14: =A13+1 -> 12 | B14: 1WB160102 | C14: 18.5113396,73.8481242 | D14: 00001WB16-1WB160101 | E14: =_xlfn.IFNA(VLOOKUP($D14,'Route-Details'!$B$2:$X$1048576,'Node Details'!E$1,0),"") -> Airtel | F14: =_xlfn.IFNA(VLOOKUP($D14,'Route-Details'!$B$2:$X$1048576,'Node Details'!F$1,0),"") -> Narayan Peth 2 | G14: =_xlfn.IFNA(VLOOKUP($D14,'Route-Details'!$B$2:$X$1048576,'Node Details'!G$1,0),"") -> Pune | H14: =_xlfn.IFNA(VLOOKUP($D14,'Route-Details'!$B$2:$X$1048576,'Node Details'!H$1,0),"") -> M&G | I14: =_xlfn.IFNA(VLOOKUP($D14,'Route-Details'!$B$2:$X$1048576,'Node Details'!I$1,0),"") -> 1WB | J14: =_xlfn.IFNA(VLOOKUP($D14,'Route-Details'!$B$2:$X$1048576,'Node Details'!J$1,0),"") -> 1WB | K14: 45046 | L14: 45107 | M14: 45112 | N14: 45107 | Q14: No | BB14: R-28 | BC14: New data for Sep-23 Audit
A15: =A14+1 -> 13 | B15: 1WB160101 | C15: 18.5114659,73.8479177 | D15: 00001WB16-1WB160101 | E15: =_xlfn.IFNA(VLOOKUP($D15,'Route-Details'!$B$2:$X$1048576,'Node Details'!E$1,0),"") -> Airtel | F15: =_xlfn.IFNA(VLOOKUP($D15,'Route-Details'!$B$2:$X$1048576,'Node Details'!F$1,0),"") -> Narayan Peth 2 | G15: =_xlfn.IFNA(VLOOKUP($D15,'Route-Details'!$B$2:$X$1048576,'Node Details'!G$1,0),"") -> Pune | H15: =_xlfn.IFNA(VLOOKUP($D15,'Route-Details'!$B$2:$X$1048576,'Node Details'!H$1,0),"") -> M&G | I15: =_xlfn.IFNA(VLOOKUP($D15,'Route-Details'!$B$2:$X$1048576,'Node Details'!I$1,0),"") -> 1WB | J15: =_xlfn.IFNA(VLOOKUP($D15,'Route-Details'!$B$2:$X$1048576,'Node Details'!J$1,0),"") -> 1WB | K15: 45046 | L15: 45107 | M15: 45112 | N15: 45107 | Q15: No | BB15: R-28 | BC15: New data for Sep-23 Audit
... A245: =A244+1 -> 243 | B245: 1PS160101 | C245: 18.512756,73.847585 | D245: 00001PS16-1PS160108 | E245: =_xlfn.IFNA(VLOOKUP($D245,'Route-Details'!$B$2:$X$1048576,'Node Details'!E$1,0),"") -> Airtel | F245: =_xlfn.IFNA(VLOOKUP($D245,'Route-Details'!$B$2:$X$1048576,'Node Details'!F$1,0),"") -> Narayan Peth 1 | G245: =_xlfn.IFNA(VLOOKUP($D245,'Route-Details'!$B$2:$X$1048576,'Node Details'!G$1,0),"") -> Pune | H245: =_xlfn.IFNA(VLOOKUP($D245,'Route-Details'!$B$2:$X$1048576,'Node Details'!H$1,0),"") -> M&G | I245: =_xlfn.IFNA(VLOOKUP($D245,'Route-Details'!$B$2:$X$1048576,'Node Details'!I$1,0),"") -> 1PS | J245: =_xlfn.IFNA(VLOOKUP($D245,'Route-Details'!$B$2:$X$1048576,'Node Details'!J$1,0),"") -> 1PS | K245: 45107 | L245: 45107 | M245: 45112 | N245: 45107 | Q245: No | BB245: R-21 | BC245: New data for Sep-23 Audit
A246: =A245+1 -> 244 | B246: 1PS | D246: 0000001PS-00001PS10 | E246: =_xlfn.IFNA(VLOOKUP($D246,'Route-Details'!$B$2:$X$1048576,'Node Details'!E$1,0),"") -> Airtel | F246: =_xlfn.IFNA(VLOOKUP($D246,'Route-Details'!$B$2:$X$1048576,'Node Details'!F$1,0),"") -> Narayan Peth 1 | G246: =_xlfn.IFNA(VLOOKUP($D246,'Route-Details'!$B$2:$X$1048576,'Node Details'!G$1,0),"") -> Pune | H246: =_xlfn.IFNA(VLOOKUP($D246,'Route-Details'!$B$2:$X$1048576,'Node Details'!H$1,0),"") -> M&G | I246: =_xlfn.IFNA(VLOOKUP($D246,'Route-Details'!$B$2:$X$1048576,'Node Details'!I$1,0),"") -> 1PS | J246: =_xlfn.IFNA(VLOOKUP($D246,'Route-Details'!$B$2:$X$1048576,'Node Details'!J$1,0),"") -> 1PS | K246: 45046 | L246: 45107 | M246: 45112 | N246: 45107 | Q246: No | BC246: New data for Sep-23 Audit
A247: =A246+1 -> 245 | B247: 1WB | D247: 0000001WB-00001WB15 | E247: =_xlfn.IFNA(VLOOKUP($D247,'Route-Details'!$B$2:$X$1048576,'Node Details'!E$1,0),"") -> Airtel | F247: =_xlfn.IFNA(VLOOKUP($D247,'Route-Details'!$B$2:$X$1048576,'Node Details'!F$1,0),"") -> Narayan Peth 2 | G247: =_xlfn.IFNA(VLOOKUP($D247,'Route-Details'!$B$2:$X$1048576,'Node Details'!G$1,0),"") -> Pune | H247: =_xlfn.IFNA(VLOOKUP($D247,'Route-Details'!$B$2:$X$1048576,'Node Details'!H$1,0),"") -> M&G | I247: =_xlfn.IFNA(VLOOKUP($D247,'Route-Details'!$B$2:$X$1048576,'Node Details'!I$1,0),"") -> 1WB | J247: =_xlfn.IFNA(VLOOKUP($D247,'Route-Details'!$B$2:$X$1048576,'Node Details'!J$1,0),"") -> 1WB | K247: 45046 | L247: 45107 | M247: 45112 | N247: 45107 | Q247: No | BC247: New data for Sep-23 Audit
A248: =A247+1 -> 246 | B248: K0E01 | C248: 18.5097769,73.8325109 | D248: 000000K0E-0000K0E04 | E248: =_xlfn.IFNA(VLOOKUP($D248,'Route-Details'!$B$2:$X$1048576,'Node Details'!E$1,0),"") -> Airtel | F248: =_xlfn.IFNA(VLOOKUP($D248,'Route-Details'!$B$2:$X$1048576,'Node Details'!F$1,0),"") -> Prabhat Rd 1 | G248: =_xlfn.IFNA(VLOOKUP($D248,'Route-Details'!$B$2:$X$1048576,'Node Details'!G$1,0),"") -> Pune | H248: =_xlfn.IFNA(VLOOKUP($D248,'Route-Details'!$B$2:$X$1048576,'Node Details'!H$1,0),"") -> M&G | I248: =_xlfn.IFNA(VLOOKUP($D248,'Route-Details'!$B$2:$X$1048576,'Node Details'!I$1,0),"") -> K0E | J248: =_xlfn.IFNA(VLOOKUP($D248,'Route-Details'!$B$2:$X$1048576,'Node Details'!J$1,0),"") -> K0E | K248: 45046 | L248: 45107 | M248: 45112 | N248: 45107 | Q248: No | BB248: R-1 | BC248: New data for Sep-23 Audit
A249: =A248+1 -> 247 | B249: K0E010101 | C249: 18.5097769,73.8325109 | D249: 0000K0E01-K0E010108 | E249: =_xlfn.IFNA(VLOOKUP($D249,'Route-Details'!$B$2:$X$1048576,'Node Details'!E$1,0),"") -> Airtel | F249: =_xlfn.IFNA(VLOOKUP($D249,'Route-Details'!$B$2:$X$1048576,'Node Details'!F$1,0),"") -> Prabhat Rd 1 | G249: =_xlfn.IFNA(VLOOKUP($D249,'Route-Details'!$B$2:$X$1048576,'Node Details'!G$1,0),"") -> Pune | H249: =_xlfn.IFNA(VLOOKUP($D249,'Route-Details'!$B$2:$X$1048576,'Node Details'!H$1,0),"") -> M&G | I249: =_xlfn.IFNA(VLOOKUP($D249,'Route-Details'!$B$2:$X$1048576,'Node Details'!I$1,0),"") -> K0E | J249: =_xlfn.IFNA(VLOOKUP($D249,'Route-Details'!$B$2:$X$1048576,'Node Details'!J$1,0),"") -> K0E | K249: 45046 | L249: 45107 | M249: 45112 | N249: 45107 | Q249: No | BB249: R-9 | BC249: New data for Sep-23 Audit
